File: src/pkynetics/data/dsc/sample_dsc_tainstruments.txt
CLOSED
Version	0.4
Run	8873
Instrument	2920 MDSC      V2.6A
Module	DSC Standard Cell
Sample	Eicosane
Size	9.00000	mg
Method	Maxime
Operator	maxime
Comment
Xcomment	Pan: Aluminum Hermetic  Gas1: Nitrogen  50 mL/min   Gas2: None
Text
Exotherm	Up
Kcell	1.07210
Cpconst	1.7601
Calib	-8.49
TempCal	1	pts	157.87	156.60
BaselineCal	0.0039	-1.0857
IsoTrackTime	0.50
Thresholds	0.000	0.0000
Controls	Gas 1  Event Off  Sampling 0.2 sec/pt
Cell#	316
Nsig	3
Sig1	Time (min)
Sig2	Temperature (øC)
Sig3	Heat Flow (mW)
Date	25-Jan-17
Time	17:45
File	C:\TA\Data\DSC\maximeflahaut\Eicosane.001
OrgFile	H:\DSC\Courbes\eicosane\eicosane 1øCmin cycle 2.001
StartOfData
-1.000000	69.19148	0.0000000
188.0995	-21.18238	-10.46110
188.2228	-21.16650	-10.46091
188.3461	-21.12226	-10.48172
188.4694	-21.05114	-10.51891
188.5927	-20.95264	-10.56046
188.7145	-20.83956	-10.59978
188.8378	-20.71582	-10.63062
188.9612	-20.59125	-10.64708
189.0827	-20.46685	-10.65577
189.2061	-20.34311	-10.65726
189.3295	-20.22049	-10.65723
189.4528	-20.09992	-10.65579
189.5761	-19.98048	-10.65337
189.6994	-19.86113	-10.64982
189.8227	-19.74023	-10.64670
189.9462	-19.61784	-10.64428
190.0695	-19.49492	-10.64317
190.1927	-19.37066	-10.64295
190.3161	-19.24606	-10.64268
190.4395	-19.12235	-10.64227
190.5628	-18.99732	-10.64196
190.6862	-18.87363	-10.64095
190.8094	-18.75058	-10.63967
190.9327	-18.62363	-10.63847
191.0545	-18.50166	-10.63704
191.1778	-18.37546	-10.63672
191.3011	-18.24611	-10.63640
191.4227	-18.12150	-10.63584
191.5461	-17.99727	-10.63524
191.6695	-17.87117	-10.63422
191.7928	-17.74587	-10.63247
191.9162	-17.62377	-10.63030
192.0395	-17.49920	-10.62820
192.1628	-17.37434	-10.62719
192.2861	-17.25006	-10.62619
192.4094	-17.12520	-10.62544
192.5327	-17.00222	-10.62466
192.6561	-16.87528	-10.62370
192.7795	-16.75140	-10.62234
192.9028	-16.62519	-10.62125
193.0262	-16.50084	-10.62014
193.1495	-16.37465	-10.61937
193.2728	-16.24958	-10.61816
193.3944	-16.12566	-10.61774
193.5178	-16.00196	-10.61675
193.6412	-15.87680	-10.61523
193.7628	-15.75380	-10.61337
193.8861	-15.63025	-10.61219
194.0094	-15.50525	-10.61127
194.1328	-15.37804	-10.61101
194.2561	-15.25302	-10.61101
194.3795	-15.12888	-10.61055
194.5028	-15.00313	-10.61017
194.6261	-14.87799	-10.60918
194.7495	-14.75180	-10.60793
194.8727	-14.62670	-10.60696
194.9962	-14.50217	-10.60625
195.1194	-14.37504	-10.60533
195.2428	-14.25068	-10.60472
195.3661	-14.12505	-10.60375
195.4894	-13.99877	-10.60293
195.6128	-13.87442	-10.60157
195.7344	-13.75025	-10.60010
195.8578	-13.62694	-10.59866
195.9811	-13.50208	-10.59737
196.1028	-13.38018	-10.59634
196.2261	-13.25441	-10.59639
196.3495	-13.12725	-10.59604
196.4727	-13.00291	-10.59540
196.5961	-12.87549	-10.59431
196.7195	-12.75172	-10.59294
196.8428	-12.62579	-10.59185
196.9662	-12.50107	-10.59075
197.0894	-12.37714	-10.58949
197.2128	-12.25334	-10.58847
197.3362	-12.12816	-10.58792
197.4594	-12.00043	-10.58709
197.5828	-11.87728	-10.58604
197.7061	-11.75202	-10.58560
197.8295	-11.62872	-10.58499
197.9527	-11.50476	-10.58406
198.0745	-11.38191	-10.58286
198.1978	-11.25628	-10.58176
198.3212	-11.13081	-10.58080
198.4427	-11.00823	-10.58032
198.5662	-10.88173	-10.58019
198.6894	-10.75555	-10.57962
198.8128	-10.63129	-10.57912
198.9361	-10.50671	-10.57838
199.0594	-10.38093	-10.57770
199.1828	-10.25534	-10.57664
199.3061	-10.13095	-10.57581
199.4295	-10.00481	-10.57480
199.5528	-9.881603	-10.57369
199.6761	-9.758015	-10.57226
199.7995	-9.632889	-10.57143
199.9228	-9.508339	-10.57016
200.0461	-9.386207	-10.56930
200.1695	-9.261793	-10.56826
200.2928	-9.138046	-10.56710
200.4144	-9.014074	-10.56583
200.5378	-8.891806	-10.56526
200.6612	-8.767655	-10.56504
200.7827	-8.646153	-10.56474
200.9061	-8.520734	-10.56445
201.0295	-8.397974	-10.56424
201.1527	-8.274978	-10.56323
201.2761	-8.149860	-10.56212
201.3994	-8.025253	-10.56083
201.5228	-7.901602	-10.56026
201.6461	-7.776681	-10.56008
201.7694	-7.650586	-10.56020
201.8928	-7.525011	-10.56024
202.0162	-7.399282	-10.56009
202.1394	-7.273943	-10.55965
202.2628	-7.148290	-10.55910
202.3862	-7.023978	-10.55844
202.5095	-6.899853	-10.55760
202.6328	-6.775988	-10.55642
202.7544	-6.650128	-10.55522
202.8778	-6.528428	-10.55451
203.0012	-6.402472	-10.55369
203.1227	-6.280506	-10.55333
203.2461	-6.154452	-10.55293
203.3694	-6.029790	-10.55286
203.4928	-5.904984	-10.55228
203.6162	-5.781454	-10.55084
203.7394	-5.658570	-10.54919
203.8628	-5.533504	-10.54795
203.9861	-5.409292	-10.54729
204.1095	-5.283965	-10.54709
204.2328	-5.160234	-10.54668
204.3561	-5.034872	-10.54597
204.4794	-4.911734	-10.54567
204.6028	-4.786539	-10.54576
204.7262	-4.662772	-10.54538
204.8495	-4.537232	-10.54507
204.9727	-4.412200	-10.54458
205.0944	-4.291446	-10.54392
205.2178	-4.166656	-10.54315
205.3412	-4.043156	-10.54240
205.4628	-3.919580	-10.54170
205.5861	-3.794187	-10.54128
205.7094	-3.668204	-10.54134
205.8328	-3.544695	-10.54101
205.9562	-3.417430	-10.54050
206.0795	-3.293872	-10.53987
206.2028	-3.168280	-10.53886
206.3262	-3.043953	-10.53833
206.4495	-2.919455	-10.53762
206.5727	-2.793488	-10.53681
206.6961	-2.670020	-10.53609
206.8194	-2.545584	-10.53592
206.9428	-2.422056	-10.53566
207.0662	-2.297667	-10.53487
207.1894	-2.171290	-10.53452
207.3128	-2.048276	-10.53429
207.4344	-1.927585	-10.53325
207.5577	-1.800711	-10.53236
207.6812	-1.678281	-10.53184
207.8028	-1.553459	-10.53146
207.9262	-1.429615	-10.53147
208.0495	-1.306335	-10.53101
208.1727	-1.182651	-10.53010
208.2961	-1.057642	-10.52906
208.4194	-0.9343375	-10.52823
208.5427	-0.8099080	-10.52772
208.6661	-0.6859780	-10.52746
208.7894	-0.5615762	-10.52700
208.9128	-0.4361742	-10.52680
209.0362	-0.3110906	-10.52657
209.1595	-0.1879373	-10.52668
209.2828	-.06354741	-10.52656
209.4062	0.06095147	-10.52593
209.5295	0.1869637	-10.52519
209.6528	0.3101688	-10.52476
209.7744	0.4326637	-10.52449
209.8978	0.5587707	-10.52416
210.0212	0.6842704	-10.52339
210.1428	0.8063528	-10.52290
210.2662	0.9290421	-10.52237
210.3895	1.054783	-10.52155
210.5128	1.179486	-10.52076
210.6362	1.303737	-10.52011
210.7595	1.427902	-10.51970
210.8828	1.551970	-10.51960
211.0062	1.675772	-10.51945
211.1295	1.799494	-10.51941
211.2528	1.925123	-10.51905
211.3760	2.048874	-10.51885
211.4994	2.174406	-10.51852
211.6227	2.297608	-10.51799
211.7462	2.424911	-10.51746
211.8695	2.547325	-10.51705
211.9928	2.673845	-10.51662
212.1144	2.795087	-10.51625
212.2377	2.920516	-10.51576
212.3611	3.044555	-10.51531
212.4827	3.164625	-10.51457
212.6062	3.289705	-10.51400
212.7295	3.413266	-10.51344
212.8528	3.538892	-10.51330
212.9762	3.663300	-10.51289
213.0994	3.785878	-10.51259
213.2227	3.910453	-10.51186
213.3461	4.036279	-10.51141
213.4694	4.159459	-10.51104
213.5928	4.284726	-10.51114
213.7162	4.409227	-10.51109
213.8395	4.534674	-10.51127
213.9628	4.659119	-10.51140
214.0860	4.783160	-10.51106
214.2094	4.907578	-10.51059
214.3328	5.032991	-10.50991
214.4545	5.155410	-10.50969
214.5778	5.281086	-10.50910
214.7011	5.402089	-10.50826
214.8227	5.527674	-10.50768
214.9462	5.648113	-10.50736
215.0695	5.774661	-10.50726
215.1928	5.899236	-10.50726
215.3160	6.022813	-10.50692
215.4394	6.148818	-10.50621
215.5628	6.270879	-10.50586
215.6862	6.394124	-10.50557
215.8094	6.520440	-10.50537
215.9328	6.641340	-10.50502
216.0562	6.765992	-10.50444
216.1795	6.889411	-10.50399
216.3027	7.013490	-10.50382
216.4260	7.137808	-10.50372
216.5495	7.261640	-10.50334
216.6728	7.385774	-10.50335
216.7945	7.509212	-10.50311
216.9178	7.632206	-10.50267
217.0410	7.756594	-10.50187
217.1628	7.878416	-10.50161
217.2862	8.004605	-10.50152
217.4095	8.130393	-10.50140
217.5327	8.254116	-10.50135
217.6560	8.376652	-10.50123
217.7795	8.501954	-10.50122
217.9028	8.626218	-10.50117
218.0260	8.749848	-10.50070
218.1495	8.875637	-10.50044
218.2728	9.001114	-10.50017
218.3961	9.123407	-10.50010
218.5194	9.247245	-10.50002
218.6428	9.371884	-10.49985
218.7662	9.495376	-10.49974
218.8894	9.618641	-10.49934
219.0128	9.743689	-10.49862
219.1345	9.866597	-10.49804
219.2578	9.990849	-10.49765
219.3811	10.11520	-10.49764
219.5028	10.23611	-10.49754
219.6262	10.36217	-10.49763
219.7494	10.48540	-10.49793
219.8727	10.60843	-10.49767
219.9962	10.73372	-10.49708
220.1195	10.85886	-10.49691
220.2428	10.98502	-10.49666
220.3660	11.10842	-10.49690
220.4894	11.22983	-10.49660
220.6128	11.35448	-10.49644
220.7362	11.47962	-10.49616
220.8594	11.60576	-10.49608
220.9827	11.73025	-10.49604
221.1060	11.85329	-10.49596
221.2295	11.97977	-10.49562
221.3528	12.10170	-10.49563
221.4744	12.22562	-10.49552
221.5978	12.34910	-10.49513
221.7212	12.47185	-10.49504
221.8428	12.59534	-10.49473
221.9661	12.71926	-10.49451
222.0894	12.84102	-10.49428
222.2128	12.96741	-10.49420
222.3362	13.09129	-10.49457
222.4595	13.21544	-10.49466
222.5828	13.33922	-10.49446
222.7060	13.46396	-10.49428
222.8294	13.58822	-10.49430
222.9527	13.71246	-10.49420
223.0760	13.83636	-10.49412
223.1994	13.96006	-10.49410
223.3227	14.08666	-10.49423
223.4461	14.21088	-10.49433
223.5694	14.33234	-10.49436
223.6927	14.45905	-10.49406
223.8144	14.57991	-10.49358
223.9378	14.70380	-10.49313
224.0612	14.82754	-10.49273
224.1828	14.95039	-10.49225
224.3062	15.07590	-10.49216
224.4295	15.19991	-10.49210
224.5528	15.32487	-10.49270
224.6762	15.44955	-10.49318
224.7995	15.57382	-10.49363
224.9228	15.70041	-10.49377
225.0461	15.82358	-10.49376
225.1694	15.94936	-10.49340
225.2927	16.07115	-10.49284
225.4162	16.19520	-10.49233
225.5395	16.31791	-10.49178
225.6628	16.44399	-10.49166
225.7862	16.56594	-10.49178
225.9094	16.69291	-10.49228
226.0327	16.81503	-10.49277
226.1543	16.93981	-10.49317
226.2777	17.06234	-10.49318
226.4012	17.18811	-10.49316
226.5228	17.31038	-10.49291
226.6462	17.43446	-10.49259
226.7694	17.55876	-10.49236
226.8927	17.68096	-10.49241
227.0160	17.80711	-10.49261
227.1395	17.93004	-10.49249
227.2628	18.05407	-10.49241
227.3862	18.17744	-10.49217
227.5095	18.30052	-10.49189
227.6327	18.42316	-10.49168
227.7560	18.54812	-10.49190
227.8794	18.67272	-10.49235
228.0028	18.79912	-10.49284
228.1260	18.92319	-10.49307
228.2494	19.04614	-10.49300
228.3727	19.17059	-10.49289
228.4944	19.29338	-10.49281
228.6178	19.41651	-10.49224
228.7411	19.54222	-10.49192
228.8628	19.66462	-10.49159
228.9860	19.78776	-10.49144
229.1094	19.91310	-10.49122
229.2327	20.03627	-10.49135
229.3562	20.16272	-10.49166
229.4795	20.28616	-10.49203
229.6028	20.41198	-10.49237
229.7262	20.53545	-10.49274
229.8495	20.66150	-10.49343
229.9728	20.78650	-10.49373
230.0962	20.91230	-10.49411
230.2195	21.03610	-10.49420
230.3428	21.16084	-10.49410
230.4662	21.28486	-10.49395
230.5895	21.40963	-10.49371
230.7128	21.53367	-10.49352
230.8344	21.65586	-10.49336
230.9577	21.78017	-10.49353
231.0811	21.90392	-10.49376
231.2027	22.02659	-10.49368
231.3260	22.15282	-10.49394
231.4494	22.27690	-10.49399
231.5727	22.40107	-10.49421
231.6961	22.52619	-10.49423
231.8194	22.65048	-10.49452
231.9427	22.77533	-10.49414
232.0662	22.90014	-10.49440
232.1895	23.02516	-10.49484
232.3128	23.15038	-10.49542
232.4362	23.27218	-10.49543
232.5594	23.39786	-10.49532
232.6827	23.52312	-10.49487
232.8060	23.64379	-10.49465
232.9294	23.76936	-10.49464
233.0528	23.89210	-10.49460
233.1745	24.01368	-10.49496
233.2978	24.13816	-10.49557
233.4210	24.26294	-10.49627
233.5427	24.38589	-10.49668
233.6660	24.51189	-10.49692
233.7894	24.63457	-10.49712
233.9128	24.75940	-10.49714
234.0362	24.88269	-10.49723
234.1595	25.00628	-10.49704
234.2827	25.12912	-10.49720
234.4060	25.25522	-10.49724
234.5295	25.37890	-10.49764
234.6528	25.50356	-10.49814
234.7762	25.62559	-10.49901
234.8994	25.75120	-10.49975
235.0227	25.87458	-10.49980
235.1462	26.00018	-10.49963
235.2695	26.12408	-10.49964
235.3928	26.24745	-10.49978
235.5144	26.37094	-10.49987
235.6377	26.49398	-10.50038
235.7611	26.61970	-10.50091
235.8828	26.74272	-10.50114
236.0062	26.86701	-10.50160
236.1295	26.99062	-10.50210
236.2527	27.11490	-10.50235
236.3760	27.23802	-10.50254
236.4995	27.36355	-10.50286
236.6228	27.48745	-10.50327
236.7462	27.61166	-10.50393
236.8694	27.73418	-10.50439
236.9927	27.86013	-10.50468
237.1160	27.98450	-10.50505
237.2395	28.10772	-10.50524
237.3628	28.23329	-10.50606
237.4860	28.35936	-10.50671
237.6094	28.48429	-10.50694
237.7328	28.60920	-10.50709
237.8544	28.73232	-10.50781
237.9778	28.85580	-10.50830
238.1012	28.98102	-10.50906
238.2228	29.10414	-10.50984
238.3461	29.22744	-10.51054
238.4694	29.35102	-10.51137
238.5928	29.47710	-10.51174
238.7162	29.60139	-10.51222
238.8394	29.72582	-10.51263
238.9628	29.84956	-10.51344
239.0860	29.97541	-10.51420
239.2095	30.09978	-10.51478
239.3328	30.22474	-10.51557
239.4560	30.34892	-10.51644
239.5794	30.47257	-10.51752
239.7028	30.59610	-10.51841
239.8262	30.72163	-10.51980
239.9494	30.84791	-10.52059
240.0728	30.97096	-10.52097
240.1945	31.09444	-10.52109
240.3178	31.21882	-10.52153
240.4411	31.33968	-10.52238
240.5628	31.46434	-10.52356
240.6862	31.59034	-10.52511
240.8095	31.71430	-10.52664
240.9327	31.83946	-10.52812
241.0560	31.96339	-10.52944
241.1795	32.08679	-10.53090
241.3028	32.21149	-10.53268
241.4260	32.33711	-10.53491
241.5494	32.46183	-10.53666
241.6728	32.58629	-10.53838
241.7962	32.71082	-10.54043
241.9194	32.83326	-10.54279
242.0427	32.95798	-10.54554
242.1660	33.07966	-10.54889
242.2895	33.20709	-10.55301
242.4128	33.33174	-10.55780
242.5345	33.45540	-10.56323
242.6578	33.57857	-10.56885
242.7812	33.70141	-10.57482
242.9027	33.82571	-10.58231
243.0260	33.94950	-10.59280
243.1495	34.07417	-10.60535
243.2728	34.19889	-10.62052
243.3961	34.32172	-10.63840
243.5194	34.44544	-10.66128
243.6428	34.56699	-10.69035
243.7662	34.68834	-10.72788
243.8894	34.81100	-10.77776
244.0128	34.92920	-10.84726
244.1362	35.04522	-10.94550
244.2594	35.16125	-11.08848
244.3828	35.26838	-11.29648
244.5062	35.37150	-11.58776
244.6294	35.46352	-11.97813
244.7527	35.55125	-12.46354
244.8745	35.62947	-13.02744
244.9978	35.70216	-13.65896
245.1212	35.77212	-14.33799
245.2427	35.83856	-15.03841
245.3660	35.90128	-15.76908
245.4894	35.96354	-16.51978
245.6128	36.02766	-17.28875
245.7362	36.08620	-18.06852
245.8595	36.14770	-18.85254
245.9827	36.21025	-19.63284
246.1060	36.27032	-20.39554
246.2295	36.33178	-21.14270
246.3528	36.39602	-21.86994
246.4760	36.46124	-22.57085
246.5994	36.53050	-23.22865
246.7228	36.60436	-23.83740
246.8462	36.68450	-24.33944
246.9694	36.76779	-24.85464
247.0927	36.85720	-25.25837
247.2144	36.95083	-25.60510
247.3378	37.06239	-25.71850
247.4612	37.17962	-25.75442
247.5827	37.31700	-25.55084
247.7060	37.47262	-25.09661
247.8295	37.64209	-24.52263
247.9528	37.81780	-23.85892
248.0760	37.98395	-23.41058
248.1995	38.12620	-23.23133
248.3228	38.31004	-22.44029
248.4462	38.52261	-21.25258
248.5694	38.88764	-18.02429
248.6927	39.25391	-14.94842
248.8162	39.55355	-12.90714
248.9395	39.78134	-11.83549
249.0628	39.96518	-11.26363
249.1862	40.12350	-10.95400
249.3095	40.26748	-10.78468
249.4327	40.40358	-10.68922
249.5544	40.53466	-10.63592
249.6778	40.66365	-10.60552
249.8011	40.79111	-10.58880
249.9227	40.91316	-10.57978
250.0462	41.03915	-10.57470
250.1694	41.16328	-10.57204
250.2927	41.28903	-10.56976
250.4162	41.41262	-10.56846
250.5394	41.53653	-10.56792
250.6628	41.66187	-10.56749
250.7862	41.78537	-10.56712
250.9094	41.91100	-10.56692
251.0328	42.03888	-10.56699
251.1562	42.16289	-10.56703
251.2794	42.28730	-10.56670
251.4028	42.41015	-10.56635
251.5260	42.53524	-10.56644
251.6494	42.66006	-10.56699
251.7728	42.78640	-10.56734
251.8944	42.90964	-10.56730
252.0178	43.03294	-10.56716
252.1411	43.15860	-10.56716
252.2628	43.28084	-10.56700
252.3862	43.40547	-10.56687
252.5094	43.53016	-10.56684
252.6328	43.65278	-10.56666
252.7562	43.77760	-10.56662
252.8795	43.90277	-10.56707
253.0027	44.02692	-10.56739
253.1260	44.15168	-10.56795
253.2495	44.27548	-10.56836
253.3728	44.40312	-10.56862
253.4962	44.52602	-10.56878
253.6195	44.64954	-10.56885
253.7427	44.77168	-10.56837
253.8660	44.89633	-10.56800
253.9895	45.01834	-10.56817
254.1128	45.14480	-10.56831
254.2344	45.26776	-10.56901
254.3578	45.39184	-10.57002
254.4812	45.51730	-10.57067
254.6027	45.64056	-10.57099
254.7260	45.76298	-10.57115
254.8495	45.88903	-10.57139
254.9727	46.01230	-10.57159
255.0961	46.13895	-10.57171
255.2195	46.26234	-10.57190
255.3427	46.38676	-10.57225
255.4662	46.51272	-10.57254
255.5894	46.63574	-10.57270
255.7128	46.76122	-10.57270
255.8360	46.88524	-10.57293
255.9595	47.00996	-10.57323
256.0828	47.13230	-10.57322
256.2060	47.25890	-10.57340
256.3295	47.38528	-10.57372
256.4527	47.51011	-10.57404
256.5744	47.63302	-10.57459
256.6978	47.75691	-10.57530
256.8210	47.88279	-10.57547
256.9428	48.00563	-10.57521
257.0662	48.12862	-10.57449
257.1894	48.25308	-10.57389
257.3128	48.37730	-10.57351
257.4362	48.49973	-10.57421
257.5594	48.62612	-10.57545
257.6828	48.75069	-10.57655
257.8060	48.87586	-10.57743
257.9294	49.00010	-10.57758
258.0528	49.12620	-10.57750
258.1760	49.24954	-10.57716
258.2995	49.37376	-10.57682
258.4228	49.49724	-10.57662
258.5461	49.62186	-10.57686
258.6695	49.74694	-10.57672
258.7928	49.87153	-10.57726
258.9145	49.99430	-10.57780
259.0376	50.11848	-10.57811
259.1612	50.24328	-10.57891
259.2827	50.36467	-10.57950
259.4062	50.48876	-10.57940
259.5295	50.61313	-10.57927
259.6527	50.73642	-10.57926
259.7762	50.86248	-10.57930
259.8995	50.98572	-10.57981
260.0227	51.10976	-10.58042
260.1462	51.23617	-10.58100
260.2695	51.35778	-10.58120
260.3927	51.48310	-10.58100
260.5160	51.60757	-10.58084
260.6395	51.72929	-10.58134
260.7628	51.85403	-10.58160
260.8860	51.97822	-10.58164
261.0095	52.10084	-10.58214
261.1328	52.22836	-10.58272
261.2544	52.34985	-10.58304
261.3777	52.47584	-10.58346
261.5012	52.60051	-10.58398
261.6228	52.72344	-10.58434
261.7461	52.84774	-10.58508
261.8694	52.97305	-10.58572
261.9928	53.09801	-10.58657
262.1162	53.22335	-10.58726
262.2394	53.34700	-10.58740
262.3628	53.46894	-10.58710
262.4862	53.59539	-10.58661
262.6095	53.72015	-10.58653
262.7327	53.84338	-10.58672
262.8560	53.96804	-10.58734
262.9794	54.09276	-10.58802
263.1028	54.21777	-10.58821
263.2262	54.34148	-10.58840
263.3495	54.46633	-10.58799
263.4727	54.59106	-10.58796
263.5944	54.71441	-10.58834
263.7178	54.83787	-10.58921
263.8412	54.96224	-10.58959
263.9628	55.08641	-10.58972
264.0862	55.20972	-10.58982
264.2095	55.33435	-10.58984
264.3328	55.45776	-10.58982
264.4560	55.58285	-10.59007
264.5794	55.70774	-10.59060
264.7028	55.83158	-10.59101
264.8262	55.95624	-10.59124
264.9495	56.08042	-10.59129
265.0728	56.20478	-10.59184
265.1962	56.33118	-10.59264
265.3195	56.45464	-10.59333
265.4428	56.58078	-10.59402
265.5660	56.70440	-10.59445
265.6894	56.82817	-10.59459
265.8128	56.95356	-10.59438
265.9345	57.07266	-10.59440
266.0578	57.19842	-10.59394
266.1811	57.32035	-10.59402
266.3028	57.44488	-10.59411
266.4260	57.56963	-10.59504
266.5495	57.69425	-10.59624
266.6728	57.81643	-10.59709
266.7962	57.94214	-10.59737
266.9194	58.06654	-10.59790
267.0428	58.19168	-10.59830
267.1660	58.31762	-10.59907
267.2895	58.44294	-10.59989
267.4128	58.56766	-10.60006
267.5362	58.69018	-10.59988
267.6594	58.81510	-10.59972
267.7827	58.93974	-10.59956
267.9060	59.06318	-10.59972
268.0295	59.18720	-10.59986
268.1528	59.31153	-10.60020
268.2744	59.43451	-10.60046
268.3978	59.55894	-10.60110
268.5212	59.68365	-10.60168
268.6428	59.80532	-10.60187
268.7660	59.93157	-10.60172
268.8894	60.05342	-10.60178
269.0128	60.17820	-10.60227
269.1360	60.30328	-10.60318
269.2594	60.42729	-10.60379
269.3827	60.55172	-10.60430
269.5060	60.67700	-10.60469
269.6294	60.80034	-10.60478
269.7528	60.92421	-10.60504
269.8762	61.04902	-10.60492
269.9995	61.17297	-10.60484
270.1228	61.29586	-10.60498
270.2462	61.42135	-10.60548
270.3695	61.54518	-10.60596
270.4928	61.67044	-10.60619
270.6145	61.79214	-10.60664
270.7378	61.91557	-10.60711
270.8611	62.04052	-10.60782
270.9828	62.16409	-10.60855
271.1062	62.28850	-10.60930
271.2295	62.41222	-10.60979
271.3528	62.53829	-10.61088
271.4760	62.66332	-10.61117
271.5994	62.78953	-10.61131
271.7228	62.91299	-10.61127
271.8462	63.03566	-10.61101
271.9695	63.16045	-10.61116
272.0928	63.28491	-10.61117
272.2160	63.40756	-10.61144
272.3394	63.53369	-10.61192
272.4628	63.65751	-10.61250
272.5862	63.78120	-10.61325
272.7095	63.90500	-10.61398
272.8328	64.02966	-10.61420
272.9544	64.15492	-10.61448
273.0778	64.27842	-10.61436
273.2012	64.40318	-10.61440
273.3228	64.52530	-10.61459
273.4462	64.65026	-10.61520
273.5694	64.77414	-10.61540
273.6928	64.89788	-10.61548
273.8160	65.02196	-10.61565
273.9395	65.14456	-10.61572
274.0628	65.27006	-10.61636
274.1862	65.39368	-10.61701
274.3094	65.51962	-10.61763
274.4328	65.64196	-10.61784
274.5562	65.76574	-10.61801
274.6795	65.89282	-10.61863
274.8028	66.01489	-10.61924
274.9260	66.14050	-10.61962
275.0494	66.26500	-10.61959
275.1728	66.38870	-10.61966
275.2944	66.51148	-10.61976
275.4178	66.63560	-10.62015
275.5412	66.75932	-10.62037
275.6628	66.88134	-10.62093
275.7862	67.00668	-10.62114
275.9095	67.12939	-10.62144
276.0327	67.25415	-10.62193
276.1560	67.37874	-10.62234
276.2794	67.50192	-10.62296
276.4028	67.62725	-10.62366
276.5262	67.75220	-10.62455
276.6495	67.87747	-10.62538
276.7728	68.00138	-10.62584
276.8962	68.12668	-10.62585
277.0195	68.24969	-10.62574
277.1428	68.37275	-10.62557
277.2660	68.49785	-10.62561
277.3894	68.62216	-10.62591
277.5128	68.74532	-10.62615
277.6345	68.86728	-10.62667
277.7578	68.99190	-10.62727
277.8812	69.11438	-10.62778
280.9961	69.64201	-10.30043
281.1179	69.64128	-10.30174
281.2412	69.62066	-10.29862
281.3628	69.57563	-10.25953
281.4860	69.50112	-10.20084
281.6094	69.40238	-10.13274
281.7328	69.28770	-10.07202
281.8562	69.16814	-10.02488
281.9795	69.04395	-9.996102
282.1028	68.92020	-9.981849
282.2262	68.79741	-9.976759
282.3495	68.67626	-9.975455
282.4727	68.55756	-9.977082
282.5961	68.43746	-9.979981
282.7195	68.32022	-9.982426
282.8428	68.20016	-9.984091
282.9662	68.08028	-9.984625
283.0894	67.95918	-9.983801
283.2128	67.83697	-9.981697
283.3345	67.71563	-9.979455
283.4578	67.59170	-9.977139
283.5812	67.46816	-9.975079
283.7028	67.34582	-9.973326
283.8262	67.22169	-9.971884
283.9494	67.09694	-9.970528
284.0728	66.97425	-9.969803
284.1962	66.84809	-9.969476
284.3195	66.72478	-9.969562
284.4428	66.60099	-9.969222
284.5660	66.47584	-9.968937
284.6895	66.35212	-9.968124
284.8128	66.22698	-9.967251
284.9362	66.10050	-9.966178
285.0594	65.97660	-9.965691
285.1828	65.84985	-9.964991
285.3060	65.72700	-9.964655
285.4294	65.60182	-9.964348
285.5528	65.47618	-9.963950
285.6744	65.35215	-9.963232
285.7978	65.22548	-9.962745
285.9210	65.10206	-9.962293
286.0428	64.97918	-9.961988
286.1662	64.85394	-9.961960
286.2895	64.72879	-9.962049
286.4128	64.60446	-9.962163
286.5362	64.48040	-9.962296
286.6595	64.35804	-9.962551
286.7828	64.23378	-9.962942
286.9062	64.10843	-9.963116
287.0295	63.98433	-9.962841
287.1528	63.85839	-9.962082
287.2762	63.73291	-9.961215
287.3995	63.60682	-9.960176
287.5228	63.48264	-9.959100
287.6462	63.35762	-9.958241
287.7695	63.23101	-9.957978
287.8928	63.10704	-9.957989
288.0145	62.98614	-9.957962
288.1378	62.86114	-9.958368
288.2612	62.73493	-9.959001
288.3828	62.61428	-9.959181
288.5060	62.48948	-9.959026
288.6294	62.36418	-9.958508
288.7528	62.24148	-9.957872
288.8762	62.11474	-9.956701
288.9995	61.98813	-9.955795
289.1228	61.86445	-9.954921
289.2462	61.73866	-9.954556
289.3695	61.61514	-9.954512
289.4928	61.49068	-9.954921
289.6162	61.36498	-9.955156
289.7395	61.24387	-9.955338
289.8628	61.11877	-9.955507
289.9862	60.99412	-9.955697
290.1095	60.87024	-9.955330
290.2328	60.74576	-9.954609
290.3543	60.62270	-9.953588
290.4778	60.49598	-9.952715
290.6010	60.37332	-9.952399
290.7227	60.24920	-9.952042
290.8461	60.12548	-9.951753
290.9694	59.99937	-9.951753
291.0928	59.87549	-9.951611
291.2160	59.75087	-9.951569
291.3394	59.62879	-9.951320
291.4628	59.50310	-9.951196
291.5862	59.37877	-9.951209
291.7095	59.25450	-9.951199
291.8328	59.12993	-9.950962
291.9562	59.00664	-9.950784
292.0795	58.88184	-9.950542
292.2028	58.75742	-9.949719
292.3262	58.63084	-9.948822
292.4495	58.50554	-9.947515
292.5728	58.38081	-9.946369
292.6945	58.25671	-9.946178
292.8178	58.13500	-9.946455
292.9411	58.00810	-9.946772
293.0628	57.88703	-9.947192
293.1860	57.76469	-9.947304
293.3094	57.63867	-9.947499
293.4328	57.51629	-9.947488
293.5561	57.39278	-9.947426
293.6795	57.26762	-9.947480
293.8028	57.14414	-9.947572
293.9262	57.01887	-9.947189
294.0495	56.89404	-9.946875
294.1728	56.77094	-9.946374
294.2961	56.64690	-9.945509
294.4194	56.52107	-9.944188
294.5428	56.39512	-9.943103
294.6662	56.27074	-9.942343
294.7895	56.14509	-9.942452
294.9128	56.02034	-9.942608
295.0345	55.89588	-9.942788
295.1578	55.77373	-9.942749
295.2810	55.65014	-9.942569
295.4028	55.52539	-9.942450
295.5260	55.40024	-9.942350
295.6494	55.27684	-9.942231
295.7727	55.15087	-9.941718
295.8962	55.02666	-9.941278
296.0195	54.90176	-9.941161
296.1428	54.77528	-9.941174
296.2662	54.64993	-9.941285
296.3894	54.52623	-9.941194
296.5128	54.40400	-9.940844
296.6360	54.27720	-9.940832
296.7594	54.15332	-9.940478
296.8827	54.02984	-9.939978
297.0062	53.90468	-9.939606
297.1295	53.78088	-9.939792
297.2528	53.65882	-9.940088
297.3745	53.53559	-9.940268
297.4978	53.40929	-9.940072
297.6210	53.28516	-9.939351
297.7428	53.16214	-9.938390
297.8660	53.03886	-9.937512
297.9894	52.91509	-9.937312
298.1128	52.79003	-9.937616
298.2362	52.66486	-9.938264
298.3595	52.54058	-9.938431
298.4827	52.41664	-9.938282
298.6060	52.29256	-9.937670
298.7294	52.16760	-9.937016
298.8528	52.04084	-9.936422
298.9760	51.91576	-9.935747
299.0994	51.79207	-9.935501
299.2227	51.66839	-9.935758
299.3462	51.54450	-9.935972
299.4694	51.41920	-9.935989
299.5928	51.29503	-9.935316
299.7144	51.17104	-9.934742
299.8376	51.04584	-9.934239
299.9611	50.92226	-9.933999
300.0828	50.79781	-9.933762
300.2060	50.67394	-9.933941
300.3294	50.55052	-9.933795
300.4528	50.42489	-9.933769
300.5760	50.30131	-9.933960
300.6994	50.17609	-9.934003
300.8228	50.05138	-9.933331
300.9462	49.92610	-9.932636
301.0695	49.80067	-9.932361
301.1928	49.67828	-9.931903
301.3162	49.55276	-9.932055
301.4395	49.42680	-9.932374
301.5628	49.30348	-9.932587
301.6862	49.18002	-9.932468
301.8095	49.05462	-9.932071
301.9328	48.93292	-9.931712
302.0545	48.80888	-9.931262
302.1778	48.68371	-9.930659
302.3010	48.55916	-9.930551
302.4228	48.43622	-9.930856
302.5462	48.31183	-9.931280
302.6695	48.18475	-9.931476
302.7928	48.06295	-9.931507
302.9160	47.93819	-9.930566
303.0394	47.81104	-9.929581
303.1628	47.68951	-9.928547
303.2862	47.56186	-9.928142
303.4095	47.43915	-9.928142
303.5328	47.31414	-9.928147
303.6560	47.19046	-9.928570
303.7794	47.06426	-9.928509
303.9028	46.94082	-9.928348
304.0262	46.81581	-9.928309
304.1495	46.69138	-9.928219
304.2727	46.56968	-9.928412
304.3944	46.44566	-9.928566
304.5178	46.32136	-9.928742
304.6412	46.19788	-9.928405
304.7628	46.07518	-9.928334
304.8860	45.94844	-9.927921
305.0095	45.82402	-9.927735
305.1328	45.70112	-9.927180
305.2560	45.57516	-9.926972
305.3795	45.44984	-9.926606
305.5028	45.32576	-9.925942
305.6260	45.20046	-9.925454
305.7494	45.07475	-9.925300
305.8728	44.94980	-9.925626
305.9961	44.82641	-9.925872
306.1194	44.70235	-9.926150
306.2428	44.57916	-9.926125
306.3662	44.45350	-9.925891
306.4894	44.32947	-9.925451
306.6128	44.20356	-9.924697
306.7345	44.08024	-9.924195
306.8577	43.95389	-9.923884
306.9810	43.82838	-9.923386
307.1028	43.70571	-9.923312
307.2262	43.58239	-9.923569
307.3494	43.45810	-9.924079
307.4727	43.33396	-9.924109
307.5962	43.20854	-9.923705
307.7195	43.08384	-9.923468
307.8428	42.95726	-9.923446
307.9661	42.83356	-9.923349
308.0895	42.70806	-9.923660
308.2128	42.58478	-9.923828
308.3360	42.45907	-9.923486
308.4595	42.33460	-9.923347
308.5828	42.20809	-9.923134
308.7060	42.08386	-9.923244
308.8295	41.96116	-9.923231
308.9528	41.83550	-9.922954
309.0744	41.71395	-9.922548
309.1978	41.58697	-9.922142
309.3212	41.46414	-9.921724
309.4428	41.33989	-9.921301
309.5660	41.21352	-9.921093
309.6894	41.09134	-9.921265
309.8128	40.96439	-9.920821
309.9362	40.84262	-9.920975
310.0594	40.71677	-9.921664
310.1828	40.59424	-9.922326
310.3062	40.46762	-9.922319
310.4295	40.34350	-9.922291
310.5528	40.22016	-9.921600
310.6760	40.09723	-9.920876
310.7994	39.96928	-9.920488
310.9228	39.84668	-9.920188
311.0461	39.72172	-9.919774
311.1695	39.59684	-9.919430
311.2928	39.47119	-9.919296
311.4145	39.34914	-9.919481
311.5378	39.22403	-9.919709
311.6612	39.09973	-9.919639
311.7828	38.97688	-9.919799
311.9060	38.85233	-9.919595
312.0294	38.72664	-9.919055
312.1528	38.60168	-9.918881
312.2760	38.47800	-9.918908
312.3994	38.35440	-9.919044
312.5227	38.22644	-9.919101
312.6462	38.10368	-9.919257
312.7695	37.97874	-9.919442
312.8928	37.85444	-9.919682
313.0162	37.72946	-9.919480
313.1395	37.60603	-9.919156
313.2628	37.48115	-9.918572
313.3862	37.35620	-9.918024
313.5095	37.22848	-9.917481
313.6327	37.10292	-9.917132
313.7544	36.98152	-9.916739
313.8778	36.85576	-9.916406
314.0012	36.73004	-9.916203
314.1228	36.60600	-9.916468
314.2461	36.48086	-9.916890
314.3694	36.35750	-9.917566
314.4928	36.23467	-9.917795
314.6162	36.10961	-9.917657
314.7394	35.98454	-9.917420
314.8628	35.86194	-9.917476
314.9862	35.73804	-9.917522
315.1095	35.61378	-9.917711
315.2327	35.48922	-9.917707
315.3562	35.36380	-9.917602
315.4794	35.23934	-9.916953
315.6028	35.11379	-9.916626
315.7262	34.99147	-9.851765
315.8494	34.97183	-8.413849
315.9727	34.91910	-7.524042
316.0945	34.86844	-6.656284
316.2178	34.81578	-5.801997
316.3412	34.75860	-4.991555
316.4628	34.70155	-4.200141
316.5860	34.64305	-3.414465
316.7095	34.58313	-2.636450
316.8328	34.52185	-1.880358
316.9560	34.45909	-1.150936
317.0795	34.39395	-0.4473062
317.2028	34.32896	0.2695928
317.3260	34.25794	0.9058601
317.4495	34.18218	1.470628
317.5728	34.09698	1.944269
317.6962	34.00280	2.275531
317.8195	33.89775	2.454066
317.9428	33.77676	2.463573
318.0662	33.64575	2.320010
318.1895	33.50307	2.071266
318.3128	33.35090	1.697893
318.4344	33.18753	1.178269
318.5578	33.00925	0.4726921
318.6812	32.81360	-0.4322039
318.8028	32.60422	-1.550105
318.9262	32.36215	-3.033413
319.0495	32.68680	4.162142
319.1728	33.24606	12.38096
319.2962	33.06587	10.78858
319.4195	32.81042	8.662322
319.5428	32.49065	5.915276
319.6660	32.01398	1.210891
319.7894	31.52932	-3.312630
319.9128	31.15210	-6.196976
320.0362	30.87064	-7.844263
320.1595	30.64980	-8.761572
320.2828	30.46830	-9.270352
320.4060	30.31055	-9.555121
320.5294	30.16622	-9.717030
320.6528	30.03172	-9.811889
320.7744	29.90052	-9.866348
320.8978	29.77294	-9.898751
321.0210	29.64791	-9.917531
321.1428	29.52330	-9.928504
321.2662	29.39516	-9.934968
321.3895	29.27271	-9.939764
321.5128	29.14482	-9.943341
321.6362	29.02062	-9.946149
321.7594	28.89386	-9.948991
321.8827	28.77007	-9.951242
322.0060	28.64582	-9.953286
322.1294	28.52117	-9.954962
322.2528	28.39730	-9.956134
322.3762	28.27017	-9.956908
322.4995	28.14644	-9.957257
322.6228	28.02094	-9.957421
322.7462	27.89669	-9.958116
322.8694	27.77144	-9.959081
322.9928	27.64576	-9.960214
323.1144	27.52451	-9.961380
323.2377	27.40123	-9.962434
323.3611	27.27610	-9.963344
323.4828	27.15129	-9.963851
323.6062	27.02667	-9.964313
323.7295	26.90294	-9.964637
323.8528	26.77766	-9.964942
323.9760	26.65172	-9.965504
324.0994	26.52886	-9.966214
324.2227	26.40620	-9.966851
324.3461	26.27930	-9.967197
324.4694	26.15353	-9.967626
324.5928	26.02994	-9.968182
324.7160	25.90612	-9.968682
324.8395	25.77915	-9.968918
324.9628	25.65619	-9.969551
325.0862	25.53058	-9.970158
325.2095	25.40600	-9.970795
325.3328	25.27982	-9.971228
325.4544	25.15736	-9.971386
325.5778	25.03238	-9.971612
325.7010	24.90892	-9.972249
325.8228	24.78711	-9.973080
325.9462	24.66278	-9.973776
326.0695	24.53784	-9.974258
326.1928	24.41238	-9.974778
326.3160	24.28726	-9.975235
326.4395	24.16204	-9.975369
326.5628	24.03859	-9.975345
326.6862	23.91010	-9.975445
326.8094	23.78601	-9.975676
326.9328	23.65967	-9.975587
327.0560	23.53596	-9.975792
327.1794	23.41292	-9.976264
327.3028	23.28683	-9.977038
327.4262	23.16278	-9.977949
327.5495	23.03932	-9.978920
327.6728	22.91511	-9.979720
327.7944	22.79162	-9.979978
327.9178	22.66680	-9.979965
328.0410	22.54039	-9.980262
328.1628	22.41918	-9.980556
328.2862	22.29601	-9.980834
328.4095	22.17030	-9.981506
328.5328	22.04564	-9.982092
328.6560	21.92227	-9.982098
328.7794	21.79661	-9.982064
328.9028	21.66899	-9.982098
329.0261	21.54644	-9.982392
329.1494	21.42108	-9.983196
329.2728	21.29724	-9.984293
329.3962	21.17463	-9.985360
329.5194	21.05104	-9.986220
329.6428	20.92804	-9.986515
329.7660	20.80200	-9.986739
329.8895	20.67698	-9.986312
330.0128	20.55093	-9.986149
330.1345	20.43139	-9.986275
330.2578	20.30539	-9.986504
330.3811	20.17880	-9.986559
330.5028	20.05703	-9.987172
330.6262	19.93248	-9.988175
330.7494	19.80846	-9.988681
330.8727	19.68600	-9.988656
330.9961	19.55868	-9.988788
331.1195	19.43456	-9.989297
331.2428	19.31149	-9.989774
331.3662	19.18741	-9.990350
331.4894	19.06111	-9.990926
331.6128	18.93811	-9.991261
331.7360	18.81469	-9.991418
331.8595	18.68986	-9.991825
331.9828	18.56540	-9.992234
332.1061	18.43927	-9.992600
332.2295	18.31523	-9.993114
332.3528	18.19237	-9.993272
332.4745	18.06906	-9.993755
332.5978	17.94368	-9.993882
332.7210	17.81901	-9.994235
332.8428	17.69534	-9.994701
332.9662	17.57259	-9.995399
333.0895	17.44921	-9.996197
333.2128	17.32235	-9.997066
333.3360	17.19992	-9.996856
333.4595	17.07559	-9.996688
333.5828	16.95110	-9.997368
333.7062	16.82923	-9.998300
333.8295	16.70260	-9.998956
333.9528	16.57811	-9.998981
334.0760	16.45322	-9.998947
334.1994	16.32839	-9.998841
334.3228	16.20342	-9.999295
334.4461	16.07920	-9.999839
334.5694	15.95652	-10.00021
334.6928	15.83161	-10.00063
334.8144	15.70716	-10.00112
334.9377	15.58214	-10.00189
335.0611	15.46024	-10.00266
335.1828	15.33711	-10.00303
335.3060	15.21299	-10.00348
335.4295	15.08714	-10.00399
335.5528	14.96260	-10.00452
335.6762	14.83853	-10.00474
335.7995	14.71472	-10.00522
335.9228	14.58691	-10.00575
336.0461	14.46527	-10.00606
336.1694	14.34049	-10.00585
336.2928	14.21869	-10.00605
336.4160	14.09353	-10.00656
336.5395	13.97042	-10.00734
336.6628	13.84479	-10.00810
336.7862	13.72270	-10.00848
336.9094	13.59668	-10.00892
337.0328	13.47128	-10.00936
337.1544	13.35011	-10.00963
337.2778	13.22667	-10.01001
337.4012	13.10334	-10.01046
337.5228	12.97877	-10.01132
337.6461	12.85580	-10.01204
337.7694	12.73045	-10.01251
337.8928	12.60743	-10.01267
338.0162	12.48442	-10.01334
338.1394	12.35915	-10.01397
338.2628	12.23667	-10.01472
338.3860	12.11129	-10.01519
338.5094	11.98689	-10.01524
338.6328	11.86257	-10.01556
338.7560	11.73873	-10.01595
338.8794	11.61558	-10.01636
339.0028	11.48992	-10.01712
339.1262	11.36571	-10.01786
339.2495	11.24212	-10.01811
339.3728	11.11723	-10.01828
339.4944	10.99444	-10.01848
339.6178	10.87206	-10.01901
339.7411	10.74863	-10.01956
339.8628	10.62463	-10.02046
339.9862	10.50069	-10.02116
340.1095	10.37619	-10.02156
340.2328	10.25133	-10.02181
340.3560	10.12666	-10.02217
340.4794	10.00432	-10.02267
340.6028	9.877012	-10.02334
340.7262	9.753289	-10.02376
340.8495	9.628924	-10.02465
340.9728	9.504536	-10.02544
341.0962	9.381046	-10.02616
341.2194	9.256906	-10.02680
341.3428	9.133626	-10.02673
341.4662	9.008519	-10.02679
341.5895	8.883376	-10.02762
341.7128	8.759400	-10.02863
341.8344	8.638038	-10.02978
341.9578	8.514304	-10.03056
342.0811	8.390891	-10.03101
342.2028	8.270820	-10.03170
342.3262	8.145290	-10.03222
342.4494	8.021550	-10.03295
342.5728	7.898298	-10.03312
342.6962	7.774472	-10.03350
342.8195	7.649234	-10.03391
342.9428	7.523945	-10.03446
343.0662	7.399278	-10.03512
343.1895	7.276462	-10.03563
343.3128	7.150543	-10.03648
343.4360	7.027960	-10.03709
343.5595	6.903116	-10.03782
343.6828	6.777134	-10.03873
343.8062	6.652545	-10.03924
343.9294	6.530078	-10.03950
344.0528	6.405854	-10.04033
344.1745	6.285070	-10.04132
344.2978	6.162239	-10.04224
344.4211	6.038304	-10.04288
344.5428	5.914956	-10.04346
344.6662	5.789856	-10.04374
344.7895	5.664269	-10.04378
344.9128	5.540312	-10.04401
345.0362	5.418049	-10.04444
345.1595	5.291060	-10.04502
345.2828	5.167937	-10.04594
345.4060	5.042826	-10.04683
345.5294	4.920715	-10.04765
345.6528	4.797700	-10.04815
345.7761	4.671938	-10.04833
345.8994	4.545264	-10.04886
346.0227	4.420964	-10.04932
346.1461	4.298838	-10.05034
346.2694	4.173864	-10.05122
346.3928	4.051284	-10.05179
346.5144	3.928598	-10.05274
346.6376	3.803916	-10.04724
346.7612	3.680728	-10.04885
346.8828	3.557387	-10.05072
347.0062	3.433410	-10.05220
347.1295	3.307522	-10.05380
347.2528	3.184111	-10.05507
347.3762	3.059569	-10.05613
347.4995	2.935685	-10.05714
347.6227	2.813715	-10.05834
347.7461	2.688715	-10.05932
347.8694	2.565475	-10.05967
347.9928	2.441912	-10.05974
348.1160	2.318787	-10.06024
348.2394	2.194069	-10.06052
348.3628	2.068961	-10.06127
348.4860	1.945292	-10.06221
348.6094	1.820924	-10.06254
348.7328	1.695983	-10.06236
348.8543	1.573929	-10.06322
348.9778	1.450059	-10.06409
349.1011	1.324888	-10.06461
349.2228	1.200046	-10.06495
349.3461	1.076496	-10.06594
349.4694	0.9519803	-10.06705
349.5928	0.8282898	-10.06783
349.7162	0.7036450	-10.06846
349.8395	0.5793495	-10.06918
349.9628	0.4546500	-10.06980
350.0860	0.3308422	-10.07046
350.2094	0.2072972	-10.07133
350.3328	0.08379113	-10.07220
350.4560	-.03993277	-10.06722
350.5795	-0.1654745	-10.06856
350.7028	-0.2888681	-10.07166
350.8262	-0.4110951	-10.07399
350.9495	-0.5374004	-10.07527
351.0728	-0.6609763	-10.07635
351.1945	-0.7831776	-10.07716
351.3178	-0.9074051	-10.07786
351.4411	-1.034412	-10.07835
351.5628	-1.157468	-10.07888
351.6861	-1.281496	-10.07951
351.8095	-1.404348	-10.08013
351.9328	-1.527693	-10.08120
352.0562	-1.654634	-10.08266
352.1795	-1.775656	-10.08382
352.3028	-1.902227	-10.08482
352.4260	-2.027103	-10.08550
352.5494	-2.150495	-10.08476
352.6728	-2.275620	-10.08538
352.7961	-2.399132	-10.08647
352.9195	-2.523641	-10.08760
353.0428	-2.648962	-10.08872
353.1662	-2.772481	-10.08940
353.2895	-2.898826	-10.09014
353.4128	-3.023386	-10.09069
353.5344	-3.145261	-10.09153
353.6578	-3.269572	-10.09317
353.7810	-3.392224	-10.09461
353.9028	-3.515446	-10.09576
354.0261	-3.641656	-10.09653
354.1494	-3.765789	-10.09678
354.2727	-3.890317	-10.09706
354.3961	-4.015868	-10.09776
354.5194	-4.139084	-10.09874
354.6428	-4.264172	-10.09968
354.7660	-4.387936	-10.10060
354.8894	-4.510439	-10.10147
355.0128	-4.635994	-10.10253
355.1360	-4.762235	-10.10322
355.2595	-4.885818	-10.10402
355.3828	-5.009518	-10.10566
355.5062	-5.137806	-10.10617
355.6295	-5.262200	-10.10591
355.7528	-5.387768	-10.10596
355.8744	-5.511970	-10.10669
355.9978	-5.636190	-10.10777
356.1210	-5.759510	-10.10989
356.2428	-5.881721	-10.11172
356.3660	-6.004790	-10.11346
356.4895	-6.127766	-10.11485
356.6128	-6.252645	-10.11584
356.7362	-6.376539	-10.11681
356.8595	-6.501268	-10.11726
356.9828	-6.625400	-10.11821
357.1062	-6.750194	-10.11897
357.2294	-6.875758	-10.11925
357.3528	-7.000482	-10.12002
357.4762	-7.125007	-10.11969
357.5995	-7.250906	-10.12009
357.7227	-7.374412	-10.12129
357.8461	-7.498829	-10.12274
357.9695	-7.623103	-10.12436
358.0928	-7.747454	-10.12582
358.2144	-7.870005	-10.12200
358.3376	-7.993900	-10.12296
358.4612	-8.120337	-10.12474
358.5828	-8.245774	-10.12698
358.7060	-8.369240	-10.12897
358.8294	-8.495001	-10.13020
358.9528	-8.617894	-10.13143
359.0762	-8.744191	-10.13261
359.1995	-8.868481	-10.13401
359.3228	-8.991674	-10.13528
359.4461	-9.113860	-10.13678
359.5695	-9.238813	-10.13791
359.6928	-9.363293	-10.13897
359.8160	-9.487399	-10.13991
359.9394	-9.612572	-10.14072
360.0628	-9.736719	-10.14184
360.1862	-9.861272	-10.14297
360.3095	-9.984356	-10.14387
360.4328	-10.10702	-10.14476
360.5544	-10.23146	-10.14543
360.6778	-10.35478	-10.14622
360.8011	-10.47987	-10.14670
360.9228	-10.60082	-10.14746
361.0462	-10.72116	-10.14930
361.1694	-10.84233	-10.15104
361.2928	-10.96670	-10.15243
361.4160	-11.09251	-10.15388
361.5395	-11.21378	-10.15535
361.6628	-11.33605	-10.15677
361.7861	-11.45978	-10.15738
361.9095	-11.58350	-10.15796
362.0328	-11.70788	-10.15864
362.1560	-11.83265	-10.15933
362.2795	-11.95472	-10.16005
362.4028	-12.08157	-10.16072
362.5261	-12.20640	-10.16177
362.6494	-12.32966	-10.16270
362.7728	-12.45301	-10.16398
362.8944	-12.57596	-10.16525
363.0178	-12.69880	-10.16644
363.1412	-12.82367	-10.16766
363.2628	-12.94460	-10.16863
363.3860	-13.07026	-10.16930
363.5094	-13.19489	-10.17026
363.6328	-13.31896	-10.17096
363.7562	-13.44504	-10.17174
363.8794	-13.56972	-10.17275
364.0028	-13.69513	-10.17364
364.1262	-13.81962	-10.17439
364.2494	-13.94458	-10.17548
364.3727	-14.06904	-10.17746
364.4962	-14.19282	-10.17904
364.6195	-14.31755	-10.18071
364.7428	-14.44070	-10.18296
364.8660	-14.56492	-10.18500
364.9894	-14.68898	-10.18638
365.1128	-14.81118	-10.18729
365.2344	-14.93480	-10.18787
365.3578	-15.05895	-10.18850
365.4812	-15.18186	-10.18926
365.6028	-15.30487	-10.19051
365.7261	-15.42926	-10.19169
365.8495	-15.55413	-10.19255
365.9727	-15.67646	-10.19378
366.0962	-15.80446	-10.19438
366.2195	-15.92722	-10.19514
366.3428	-16.05353	-10.19633
366.4662	-16.17771	-10.19725
366.5895	-16.30127	-10.18481
366.7128	-16.42648	-10.18661
366.8360	-16.55213	-10.19348
366.9595	-16.67431	-10.19835
367.0828	-16.79883	-10.20226
367.2060	-16.92301	-10.20524
367.3295	-17.04649	-10.20808
367.4528	-17.17040	-10.21028
367.5744	-17.29318	-10.21166
367.6978	-17.41752	-10.21274
367.8212	-17.53925	-10.21303
367.9428	-17.66659	-10.21369
368.0662	-17.79016	-10.21467
368.1895	-17.91419	-10.21582
368.3128	-18.03792	-10.21772
368.4360	-18.16144	-10.21942
368.5594	-18.28572	-10.22114
368.6828	-18.40935	-10.22323
368.8062	-18.53381	-10.22488
368.9295	-18.65825	-10.22614
369.0528	-18.78172	-10.22688
369.1762	-18.90811	-10.22783
369.2994	-19.03315	-10.22859
369.4228	-19.15880	-10.22930
369.5461	-19.28465	-10.22993
369.6694	-19.41058	-10.23116
369.7928	-19.53506	-10.23259
369.9145	-19.65598	-10.23461
370.0378	-19.78107	-10.23634
370.1612	-19.90602	-10.23823
370.2828	-20.02606	-10.24015
370.4062	-20.15058	-10.24216
370.5295	-20.27489	-10.24364
370.6528	-20.40111	-10.24469
370.7761	-20.52377	-10.24546
370.8994	-20.64928	-10.24605
-1.000000	-20.74431	0.0000000